2023-06-23 17:48:19 ERROR [12680-Thread-1 (process_request_thread)] log.log_response line 241: Internal Server Error: /blog/subjects/
Traceback (most recent call last):
  File "C:\Users\MyNetdisk\AppData\Local\Programs\Python\Python311\Lib\site-packages\django\urls\base.py", line 71, in reverse
    extra, resolver = resolver.namespace_dict[ns]
                      ~~~~~~~~~~~~~~~~~~~~~~~^^^^
KeyError: 'djdt'

During handling of the above exception, another exception occurred:

Traceback (most recent call last):
  File "C:\Users\MyNetdisk\AppData\Local\Programs\Python\Python311\Lib\site-packages\django\core\handlers\exception.py", line 55, in inner
    response = get_response(request)
               ^^^^^^^^^^^^^^^^^^^^^
  File "C:\Users\MyNetdisk\AppData\Local\Programs\Python\Python311\Lib\site-packages\debug_toolbar\middleware.py", line 74, in __call__
    rendered = toolbar.render_toolbar()
               ^^^^^^^^^^^^^^^^^^^^^^^^
  File "C:\Users\MyNetdisk\AppData\Local\Programs\Python\Python311\Lib\site-packages\debug_toolbar\toolbar.py", line 82, in render_toolbar
    return render_to_string("debug_toolbar/base.html", context)
           ^^^^^^^^^^^^^^^^^^^^^^^^^^^^^^^^^^^^^^^^^^^^^^^^^^^^
  File "C:\Users\MyNetdisk\AppData\Local\Programs\Python\Python311\Lib\site-packages\django\template\loader.py", line 62, in render_to_string
    return template.render(context, request)
           ^^^^^^^^^^^^^^^^^^^^^^^^^^^^^^^^^
  File "C:\Users\MyNetdisk\AppData\Local\Programs\Python\Python311\Lib\site-packages\django\template\backends\django.py", line 61, in render
    return self.template.render(context)
           ^^^^^^^^^^^^^^^^^^^^^^^^^^^^^
  File "C:\Users\MyNetdisk\AppData\Local\Programs\Python\Python311\Lib\site-packages\django\template\base.py", line 175, in render
    return self._render(context)
           ^^^^^^^^^^^^^^^^^^^^^
  File "C:\Users\MyNetdisk\AppData\Local\Programs\Python\Python311\Lib\site-packages\django\test\utils.py", line 112, in instrumented_test_render
    return self.nodelist.render(context)
           ^^^^^^^^^^^^^^^^^^^^^^^^^^^^^
  File "C:\Users\MyNetdisk\AppData\Local\Programs\Python\Python311\Lib\site-packages\django\template\base.py", line 1005, in render
    return SafeString("".join([node.render_annotated(context) for node in self]))
                              ^^^^^^^^^^^^^^^^^^^^^^^^^^^^^^^^^^^^^^^^^^^^^^^^^
  File "C:\Users\MyNetdisk\AppData\Local\Programs\Python\Python311\Lib\site-packages\django\template\base.py", line 1005, in <listcomp>
    return SafeString("".join([node.render_annotated(context) for node in self]))
                               ^^^^^^^^^^^^^^^^^^^^^^^^^^^^^^
  File "C:\Users\MyNetdisk\AppData\Local\Programs\Python\Python311\Lib\site-packages\django\template\base.py", line 966, in render_annotated
    return self.render(context)
           ^^^^^^^^^^^^^^^^^^^^
  File "C:\Users\MyNetdisk\AppData\Local\Programs\Python\Python311\Lib\site-packages\django\template\defaulttags.py", line 321, in render
    return nodelist.render(context)
           ^^^^^^^^^^^^^^^^^^^^^^^^
  File "C:\Users\MyNetdisk\AppData\Local\Programs\Python\Python311\Lib\site-packages\django\template\base.py", line 1005, in render
    return SafeString("".join([node.render_annotated(context) for node in self]))
                              ^^^^^^^^^^^^^^^^^^^^^^^^^^^^^^^^^^^^^^^^^^^^^^^^^
  File "C:\Users\MyNetdisk\AppData\Local\Programs\Python\Python311\Lib\site-packages\django\template\base.py", line 1005, in <listcomp>
    return SafeString("".join([node.render_annotated(context) for node in self]))
                               ^^^^^^^^^^^^^^^^^^^^^^^^^^^^^^
  File "C:\Users\MyNetdisk\AppData\Local\Programs\Python\Python311\Lib\site-packages\django\template\base.py", line 966, in render_annotated
    return self.render(context)
           ^^^^^^^^^^^^^^^^^^^^
  File "C:\Users\MyNetdisk\AppData\Local\Programs\Python\Python311\Lib\site-packages\django\template\defaulttags.py", line 471, in render
    url = reverse(view_name, args=args, kwargs=kwargs, current_app=current_app)
          ^^^^^^^^^^^^^^^^^^^^^^^^^^^^^^^^^^^^^^^^^^^^^^^^^^^^^^^^^^^^^^^^^^^^^
  File "C:\Users\MyNetdisk\AppData\Local\Programs\Python\Python311\Lib\site-packages\django\urls\base.py", line 82, in reverse
    raise NoReverseMatch("%s is not a registered namespace" % key)
django.urls.exceptions.NoReverseMatch: 'djdt' is not a registered namespace
2023-06-23 17:48:19 ERROR [12680-Thread-1 (process_request_thread)] basehttp.log_message line 212: "GET /blog/subjects/ HTTP/1.1" 500 139909
2023-06-23 17:49:58 ERROR [12460-Thread-1 (process_request_thread)] log.log_response line 241: Internal Server Error: /blog/subjects/
Traceback (most recent call last):
  File "C:\Users\MyNetdisk\AppData\Local\Programs\Python\Python311\Lib\site-packages\django\urls\base.py", line 71, in reverse
    extra, resolver = resolver.namespace_dict[ns]
                      ~~~~~~~~~~~~~~~~~~~~~~~^^^^
KeyError: 'djdt'

During handling of the above exception, another exception occurred:

Traceback (most recent call last):
  File "C:\Users\MyNetdisk\AppData\Local\Programs\Python\Python311\Lib\site-packages\django\core\handlers\exception.py", line 55, in inner
    response = get_response(request)
               ^^^^^^^^^^^^^^^^^^^^^
  File "C:\Users\MyNetdisk\AppData\Local\Programs\Python\Python311\Lib\site-packages\debug_toolbar\middleware.py", line 74, in __call__
    rendered = toolbar.render_toolbar()
               ^^^^^^^^^^^^^^^^^^^^^^^^
  File "C:\Users\MyNetdisk\AppData\Local\Programs\Python\Python311\Lib\site-packages\debug_toolbar\toolbar.py", line 82, in render_toolbar
    return render_to_string("debug_toolbar/base.html", context)
           ^^^^^^^^^^^^^^^^^^^^^^^^^^^^^^^^^^^^^^^^^^^^^^^^^^^^
  File "C:\Users\MyNetdisk\AppData\Local\Programs\Python\Python311\Lib\site-packages\django\template\loader.py", line 62, in render_to_string
    return template.render(context, request)
           ^^^^^^^^^^^^^^^^^^^^^^^^^^^^^^^^^
  File "C:\Users\MyNetdisk\AppData\Local\Programs\Python\Python311\Lib\site-packages\django\template\backends\django.py", line 61, in render
    return self.template.render(context)
           ^^^^^^^^^^^^^^^^^^^^^^^^^^^^^
  File "C:\Users\MyNetdisk\AppData\Local\Programs\Python\Python311\Lib\site-packages\django\template\base.py", line 175, in render
    return self._render(context)
           ^^^^^^^^^^^^^^^^^^^^^
  File "C:\Users\MyNetdisk\AppData\Local\Programs\Python\Python311\Lib\site-packages\django\test\utils.py", line 112, in instrumented_test_render
    return self.nodelist.render(context)
           ^^^^^^^^^^^^^^^^^^^^^^^^^^^^^
  File "C:\Users\MyNetdisk\AppData\Local\Programs\Python\Python311\Lib\site-packages\django\template\base.py", line 1005, in render
    return SafeString("".join([node.render_annotated(context) for node in self]))
                              ^^^^^^^^^^^^^^^^^^^^^^^^^^^^^^^^^^^^^^^^^^^^^^^^^
  File "C:\Users\MyNetdisk\AppData\Local\Programs\Python\Python311\Lib\site-packages\django\template\base.py", line 1005, in <listcomp>
    return SafeString("".join([node.render_annotated(context) for node in self]))
                               ^^^^^^^^^^^^^^^^^^^^^^^^^^^^^^
  File "C:\Users\MyNetdisk\AppData\Local\Programs\Python\Python311\Lib\site-packages\django\template\base.py", line 966, in render_annotated
    return self.render(context)
           ^^^^^^^^^^^^^^^^^^^^
  File "C:\Users\MyNetdisk\AppData\Local\Programs\Python\Python311\Lib\site-packages\django\template\defaulttags.py", line 321, in render
    return nodelist.render(context)
           ^^^^^^^^^^^^^^^^^^^^^^^^
  File "C:\Users\MyNetdisk\AppData\Local\Programs\Python\Python311\Lib\site-packages\django\template\base.py", line 1005, in render
    return SafeString("".join([node.render_annotated(context) for node in self]))
                              ^^^^^^^^^^^^^^^^^^^^^^^^^^^^^^^^^^^^^^^^^^^^^^^^^
  File "C:\Users\MyNetdisk\AppData\Local\Programs\Python\Python311\Lib\site-packages\django\template\base.py", line 1005, in <listcomp>
    return SafeString("".join([node.render_annotated(context) for node in self]))
                               ^^^^^^^^^^^^^^^^^^^^^^^^^^^^^^
  File "C:\Users\MyNetdisk\AppData\Local\Programs\Python\Python311\Lib\site-packages\django\template\base.py", line 966, in render_annotated
    return self.render(context)
           ^^^^^^^^^^^^^^^^^^^^
  File "C:\Users\MyNetdisk\AppData\Local\Programs\Python\Python311\Lib\site-packages\django\template\defaulttags.py", line 471, in render
    url = reverse(view_name, args=args, kwargs=kwargs, current_app=current_app)
          ^^^^^^^^^^^^^^^^^^^^^^^^^^^^^^^^^^^^^^^^^^^^^^^^^^^^^^^^^^^^^^^^^^^^^
  File "C:\Users\MyNetdisk\AppData\Local\Programs\Python\Python311\Lib\site-packages\django\urls\base.py", line 82, in reverse
    raise NoReverseMatch("%s is not a registered namespace" % key)
django.urls.exceptions.NoReverseMatch: 'djdt' is not a registered namespace
2023-06-23 17:49:58 ERROR [12460-Thread-1 (process_request_thread)] basehttp.log_message line 212: "GET /blog/subjects/ HTTP/1.1" 500 139909
2023-06-23 17:50:05 ERROR [12460-Thread-1 (process_request_thread)] log.log_response line 241: Internal Server Error: /
Traceback (most recent call last):
  File "C:\Users\MyNetdisk\AppData\Local\Programs\Python\Python311\Lib\site-packages\django\urls\base.py", line 71, in reverse
    extra, resolver = resolver.namespace_dict[ns]
                      ~~~~~~~~~~~~~~~~~~~~~~~^^^^
KeyError: 'djdt'

During handling of the above exception, another exception occurred:

Traceback (most recent call last):
  File "C:\Users\MyNetdisk\AppData\Local\Programs\Python\Python311\Lib\site-packages\django\core\handlers\exception.py", line 55, in inner
    response = get_response(request)
               ^^^^^^^^^^^^^^^^^^^^^
  File "C:\Users\MyNetdisk\AppData\Local\Programs\Python\Python311\Lib\site-packages\debug_toolbar\middleware.py", line 74, in __call__
    rendered = toolbar.render_toolbar()
               ^^^^^^^^^^^^^^^^^^^^^^^^
  File "C:\Users\MyNetdisk\AppData\Local\Programs\Python\Python311\Lib\site-packages\debug_toolbar\toolbar.py", line 82, in render_toolbar
    return render_to_string("debug_toolbar/base.html", context)
           ^^^^^^^^^^^^^^^^^^^^^^^^^^^^^^^^^^^^^^^^^^^^^^^^^^^^
  File "C:\Users\MyNetdisk\AppData\Local\Programs\Python\Python311\Lib\site-packages\django\template\loader.py", line 62, in render_to_string
    return template.render(context, request)
           ^^^^^^^^^^^^^^^^^^^^^^^^^^^^^^^^^
  File "C:\Users\MyNetdisk\AppData\Local\Programs\Python\Python311\Lib\site-packages\django\template\backends\django.py", line 61, in render
    return self.template.render(context)
           ^^^^^^^^^^^^^^^^^^^^^^^^^^^^^
  File "C:\Users\MyNetdisk\AppData\Local\Programs\Python\Python311\Lib\site-packages\django\template\base.py", line 175, in render
    return self._render(context)
           ^^^^^^^^^^^^^^^^^^^^^
  File "C:\Users\MyNetdisk\AppData\Local\Programs\Python\Python311\Lib\site-packages\django\test\utils.py", line 112, in instrumented_test_render
    return self.nodelist.render(context)
           ^^^^^^^^^^^^^^^^^^^^^^^^^^^^^
  File "C:\Users\MyNetdisk\AppData\Local\Programs\Python\Python311\Lib\site-packages\django\template\base.py", line 1005, in render
    return SafeString("".join([node.render_annotated(context) for node in self]))
                              ^^^^^^^^^^^^^^^^^^^^^^^^^^^^^^^^^^^^^^^^^^^^^^^^^
  File "C:\Users\MyNetdisk\AppData\Local\Programs\Python\Python311\Lib\site-packages\django\template\base.py", line 1005, in <listcomp>
    return SafeString("".join([node.render_annotated(context) for node in self]))
                               ^^^^^^^^^^^^^^^^^^^^^^^^^^^^^^
  File "C:\Users\MyNetdisk\AppData\Local\Programs\Python\Python311\Lib\site-packages\django\template\base.py", line 966, in render_annotated
    return self.render(context)
           ^^^^^^^^^^^^^^^^^^^^
  File "C:\Users\MyNetdisk\AppData\Local\Programs\Python\Python311\Lib\site-packages\django\template\defaulttags.py", line 321, in render
    return nodelist.render(context)
           ^^^^^^^^^^^^^^^^^^^^^^^^
  File "C:\Users\MyNetdisk\AppData\Local\Programs\Python\Python311\Lib\site-packages\django\template\base.py", line 1005, in render
    return SafeString("".join([node.render_annotated(context) for node in self]))
                              ^^^^^^^^^^^^^^^^^^^^^^^^^^^^^^^^^^^^^^^^^^^^^^^^^
  File "C:\Users\MyNetdisk\AppData\Local\Programs\Python\Python311\Lib\site-packages\django\template\base.py", line 1005, in <listcomp>
    return SafeString("".join([node.render_annotated(context) for node in self]))
                               ^^^^^^^^^^^^^^^^^^^^^^^^^^^^^^
  File "C:\Users\MyNetdisk\AppData\Local\Programs\Python\Python311\Lib\site-packages\django\template\base.py", line 966, in render_annotated
    return self.render(context)
           ^^^^^^^^^^^^^^^^^^^^
  File "C:\Users\MyNetdisk\AppData\Local\Programs\Python\Python311\Lib\site-packages\django\template\defaulttags.py", line 471, in render
    url = reverse(view_name, args=args, kwargs=kwargs, current_app=current_app)
          ^^^^^^^^^^^^^^^^^^^^^^^^^^^^^^^^^^^^^^^^^^^^^^^^^^^^^^^^^^^^^^^^^^^^^
  File "C:\Users\MyNetdisk\AppData\Local\Programs\Python\Python311\Lib\site-packages\django\urls\base.py", line 82, in reverse
    raise NoReverseMatch("%s is not a registered namespace" % key)
django.urls.exceptions.NoReverseMatch: 'djdt' is not a registered namespace
2023-06-23 17:50:05 ERROR [12460-Thread-1 (process_request_thread)] basehttp.log_message line 212: "GET / HTTP/1.1" 500 139775
2023-06-23 17:54:56 WARNING [8468-Thread-2 (process_request_thread)] basehttp.log_message line 212: "GET /static/images/%E5%85%B3%E9%87%8D%E4%BB%B6%E4%B8%8D%E5%90%88%E6%A0%BC%E9%A1%B9%E5%88%86%E5%B8%83_1.png HTTP/1.1" 404 1933
2023-06-23 18:30:35 ERROR [8280-Thread-2 (process_request_thread)] log.log_response line 241: Internal Server Error: /blog/excel/
Traceback (most recent call last):
  File "C:\Users\MyNetdisk\AppData\Local\Programs\Python\Python311\Lib\site-packages\django\core\handlers\exception.py", line 55, in inner
    response = get_response(request)
               ^^^^^^^^^^^^^^^^^^^^^
  File "D:\Project\DjangoBlogs\blog\middlewares.py", line 19, in wrapper
    if request.is_ajax():
       ^^^^^^^^^^^^^^^
AttributeError: 'WSGIRequest' object has no attribute 'is_ajax'
2023-06-23 18:30:35 ERROR [8280-Thread-2 (process_request_thread)] basehttp.log_message line 212: "GET /blog/excel/ HTTP/1.1" 500 71882
2023-06-23 18:31:29 ERROR [20876-Thread-1 (process_request_thread)] log.log_response line 241: Internal Server Error: /blog/excel/
Traceback (most recent call last):
  File "C:\Users\MyNetdisk\AppData\Local\Programs\Python\Python311\Lib\site-packages\django\core\handlers\exception.py", line 55, in inner
    response = get_response(request)
               ^^^^^^^^^^^^^^^^^^^^^
  File "D:\Project\DjangoBlogs\blog\middlewares.py", line 20, in wrapper
    if request.is_ajax():
       ^^^^^^^^^^^^^^^
AttributeError: 'WSGIRequest' object has no attribute 'is_ajax'
2023-06-23 18:31:30 ERROR [20876-Thread-1 (process_request_thread)] basehttp.log_message line 212: "GET /blog/excel/ HTTP/1.1" 500 71982
2023-06-23 18:32:19 ERROR [14656-Thread-1 (process_request_thread)] log.log_response line 241: Internal Server Error: /blog/excel/
Traceback (most recent call last):
  File "C:\Users\MyNetdisk\AppData\Local\Programs\Python\Python311\Lib\site-packages\django\core\handlers\exception.py", line 55, in inner
    response = get_response(request)
               ^^^^^^^^^^^^^^^^^^^^^
  File "D:\Project\DjangoBlogs\blog\middlewares.py", line 20, in wrapper
    if request.is_ajax():
       ^^^^^^^^^^^^^^^
AttributeError: 'WSGIRequest' object has no attribute 'is_ajax'
2023-06-23 18:32:19 ERROR [14656-Thread-1 (process_request_thread)] basehttp.log_message line 212: "GET /blog/excel/ HTTP/1.1" 500 71982
2023-06-23 18:32:40 ERROR [14656-Thread-1 (process_request_thread)] log.log_response line 241: Internal Server Error: /blog/excel/
Traceback (most recent call last):
  File "C:\Users\MyNetdisk\AppData\Local\Programs\Python\Python311\Lib\site-packages\django\core\handlers\exception.py", line 55, in inner
    response = get_response(request)
               ^^^^^^^^^^^^^^^^^^^^^
  File "D:\Project\DjangoBlogs\blog\middlewares.py", line 20, in wrapper
    if request.is_ajax():
       ^^^^^^^^^^^^^^^
AttributeError: 'WSGIRequest' object has no attribute 'is_ajax'
2023-06-23 18:32:40 ERROR [14656-Thread-1 (process_request_thread)] basehttp.log_message line 212: "GET /blog/excel/ HTTP/1.1" 500 71845
2023-06-23 18:34:00 WARNING [15140-Thread-1 (process_request_thread)] log.log_response line 241: Not Found: /login/
2023-06-23 18:34:00 WARNING [15140-Thread-1 (process_request_thread)] basehttp.log_message line 212: "GET /login/?backurl=/blog/excel/ HTTP/1.1" 404 11422
2023-06-23 18:34:34 WARNING [11932-Thread-1 (process_request_thread)] log.log_response line 241: Not Found: /login/
2023-06-23 18:34:34 WARNING [11932-Thread-1 (process_request_thread)] basehttp.log_message line 212: "GET /login/?backurl=/blog/excel/ HTTP/1.1" 404 11421
2023-06-23 18:34:42 WARNING [11932-Thread-1 (process_request_thread)] log.log_response line 241: Not Found: /excel
2023-06-23 18:34:42 WARNING [11932-Thread-1 (process_request_thread)] basehttp.log_message line 212: "GET /excel HTTP/1.1" 404 11376
2023-06-24 15:04:54 WARNING [8496-Thread-1 (process_request_thread)] log.log_response line 241: Not Found: /favicon.ico
2023-06-24 15:04:54 WARNING [8496-Thread-1 (process_request_thread)] basehttp.log_message line 212: "GET /favicon.ico HTTP/1.1" 404 11400
2023-06-24 15:15:53 WARNING [6256-Thread-2 (process_request_thread)] basehttp.log_message line 212: "GET /static/subjects.html HTTP/1.1" 404 1798
2023-06-24 15:16:20 WARNING [6256-Thread-3 (process_request_thread)] log.log_response line 241: Not Found: /subjects.html
2023-06-24 15:16:20 WARNING [6256-Thread-3 (process_request_thread)] basehttp.log_message line 212: "GET /subjects.html HTTP/1.1" 404 11408
2023-06-24 15:19:17 WARNING [6256-Thread-3 (process_request_thread)] basehttp.log_message line 212: "GET /static/images/hot-icon-small.png HTTP/1.1" 404 1834
2023-06-24 15:19:31 WARNING [6256-Thread-5 (process_request_thread)] basehttp.log_message line 212: "GET /static/images/hot-icon-small.png HTTP/1.1" 404 1834
2023-06-24 15:20:39 WARNING [6256-Thread-6 (process_request_thread)] basehttp.log_message line 212: "GET /static/images/%E5%85%B3%E9%87%8D%E4%BB%B6%E4%B8%8D%E5%90%88%E6%A0%BC%E9%A1%B9%E5%88%86%E5%B8%83_1.png HTTP/1.1" 404 1933
2023-06-24 15:20:43 WARNING [6256-Thread-7 (process_request_thread)] basehttp.log_message line 212: "GET /static/images/%E5%85%B3%E9%87%8D%E4%BB%B6%E4%B8%8D%E5%90%88%E6%A0%BC%E9%A1%B9%E5%88%86%E5%B8%83_1.png HTTP/1.1" 404 1933
2023-06-24 15:21:02 WARNING [6256-Thread-8 (process_request_thread)] log.log_response line 241: Not Found: /blog/teachers/echarts.html
2023-06-24 15:21:02 WARNING [6256-Thread-8 (process_request_thread)] basehttp.log_message line 212: "GET /blog/teachers/echarts.html HTTP/1.1" 404 13279
2023-06-24 15:22:36 WARNING [6256-Thread-8 (process_request_thread)] log.log_response line 241: Not Found: /blog/subjects/login.html
2023-06-24 15:22:36 WARNING [6256-Thread-8 (process_request_thread)] basehttp.log_message line 212: "GET /blog/subjects/login.html HTTP/1.1" 404 13271
2023-06-24 16:12:04 WARNING [11876-Thread-5 (process_request_thread)] log.log_response line 241: Not Found: /blog/api/restful/subjects/
2023-06-24 16:12:04 WARNING [11876-Thread-5 (process_request_thread)] basehttp.log_message line 212: "GET /blog/api/restful/subjects/ HTTP/1.1" 404 13279
2023-06-24 16:24:37 WARNING [2528-Thread-2 (process_request_thread)] log.log_response line 241: Not Found: /blog/api/restful/teachers/
2023-06-24 16:24:37 WARNING [2528-Thread-2 (process_request_thread)] basehttp.log_message line 212: "GET /blog/api/restful/teachers/ HTTP/1.1" 404 13452
2023-06-24 16:24:57 WARNING [14000-Thread-1 (process_request_thread)] log.log_response line 241: Not Found: /blog/api/restful/teachers/
2023-06-24 16:24:57 WARNING [14000-Thread-1 (process_request_thread)] basehttp.log_message line 212: "GET /blog/api/restful/teachers/ HTTP/1.1" 404 14383
2023-06-24 16:25:35 WARNING [2024-Thread-1 (process_request_thread)] log.log_response line 241: Not Found: /blog/api/restful/teachers/
2023-06-24 16:25:35 WARNING [2024-Thread-1 (process_request_thread)] basehttp.log_message line 212: "GET /blog/api/restful/teachers/ HTTP/1.1" 404 14383
2023-06-24 16:28:21 WARNING [2024-Thread-1 (process_request_thread)] log.log_response line 241: Not Found: /blog//static/html/subjects.html
2023-06-24 16:28:21 WARNING [2024-Thread-1 (process_request_thread)] basehttp.log_message line 212: "GET /blog//static/html/subjects.html HTTP/1.1" 404 13645
2023-06-24 16:28:29 WARNING [2024-Thread-1 (process_request_thread)] basehttp.log_message line 212: "GET /static/images/hot-icon-small.png HTTP/1.1" 404 1834
2023-06-24 16:39:15 WARNING [2024-Thread-4 (process_request_thread)] log.log_response line 241: Not Found: /blog/api/restful/teachers/
2023-06-24 16:39:15 WARNING [2024-Thread-4 (process_request_thread)] basehttp.log_message line 212: "GET /blog/api/restful/teachers/?sno=1 HTTP/1.1" 404 0
2023-06-24 16:39:44 WARNING [2024-Thread-4 (process_request_thread)] log.log_response line 241: Not Found: /blog/api/restful/teachers/
2023-06-24 16:39:44 WARNING [2024-Thread-4 (process_request_thread)] basehttp.log_message line 212: "GET /blog/api/restful/teachers/?sno=4 HTTP/1.1" 404 0
2023-06-24 16:39:52 WARNING [2024-Thread-4 (process_request_thread)] log.log_response line 241: Not Found: /blog/api/restful/teachers/
2023-06-24 16:39:52 WARNING [2024-Thread-4 (process_request_thread)] basehttp.log_message line 212: "GET /blog/api/restful/teachers/?sno=5 HTTP/1.1" 404 0
2023-06-24 16:40:02 WARNING [2024-Thread-4 (process_request_thread)] log.log_response line 241: Not Found: /blog/api/restful/teachers/
2023-06-24 16:40:02 WARNING [2024-Thread-4 (process_request_thread)] basehttp.log_message line 212: "GET /blog/api/restful/teachers/?sno=4 HTTP/1.1" 404 0
2023-06-24 16:40:06 WARNING [2024-Thread-4 (process_request_thread)] basehttp.log_message line 212: "GET /static/images/hot-icon-small.png HTTP/1.1" 404 1834
2023-06-24 16:53:44 ERROR [12064-Thread-1 (process_request_thread)] log.log_response line 241: Internal Server Error: /blog/api/restful/teachers/
Traceback (most recent call last):
  File "C:\Users\MyNetdisk\AppData\Local\Programs\Python\Python311\Lib\site-packages\django\core\handlers\exception.py", line 55, in inner
    response = get_response(request)
               ^^^^^^^^^^^^^^^^^^^^^
  File "C:\Users\MyNetdisk\AppData\Local\Programs\Python\Python311\Lib\site-packages\django\core\handlers\base.py", line 197, in _get_response
    response = wrapped_callback(request, *callback_args, **callback_kwargs)
               ^^^^^^^^^^^^^^^^^^^^^^^^^^^^^^^^^^^^^^^^^^^^^^^^^^^^^^^^^^^^
  File "C:\Users\MyNetdisk\AppData\Local\Programs\Python\Python311\Lib\site-packages\django\views\decorators\csrf.py", line 56, in wrapper_view
    return view_func(*args, **kwargs)
           ^^^^^^^^^^^^^^^^^^^^^^^^^^
  File "C:\Users\MyNetdisk\AppData\Local\Programs\Python\Python311\Lib\site-packages\django\views\generic\base.py", line 104, in view
    return self.dispatch(request, *args, **kwargs)
           ^^^^^^^^^^^^^^^^^^^^^^^^^^^^^^^^^^^^^^^
  File "C:\Users\MyNetdisk\AppData\Local\Programs\Python\Python311\Lib\site-packages\rest_framework\views.py", line 509, in dispatch
    response = self.handle_exception(exc)
               ^^^^^^^^^^^^^^^^^^^^^^^^^^
  File "C:\Users\MyNetdisk\AppData\Local\Programs\Python\Python311\Lib\site-packages\rest_framework\views.py", line 469, in handle_exception
    self.raise_uncaught_exception(exc)
  File "C:\Users\MyNetdisk\AppData\Local\Programs\Python\Python311\Lib\site-packages\rest_framework\views.py", line 480, in raise_uncaught_exception
    raise exc
  File "C:\Users\MyNetdisk\AppData\Local\Programs\Python\Python311\Lib\site-packages\rest_framework\views.py", line 506, in dispatch
    response = handler(request, *args, **kwargs)
               ^^^^^^^^^^^^^^^^^^^^^^^^^^^^^^^^^
  File "C:\Users\MyNetdisk\AppData\Local\Programs\Python\Python311\Lib\site-packages\rest_framework\decorators.py", line 50, in handler
    return func(*args, **kwargs)
           ^^^^^^^^^^^^^^^^^^^^^
  File "D:\Project\DjangoBlogs\blog\views.py", line 224, in show_teachers_api_restful
    subject = Subject.objects.only('name').get(no == sno)
                                               ^^
NameError: name 'no' is not defined
2023-06-24 16:53:44 ERROR [12064-Thread-1 (process_request_thread)] basehttp.log_message line 212: "GET /blog/api/restful/teachers/?sno=3 HTTP/1.1" 500 108811
2023-06-24 16:53:57 WARNING [10988-Thread-1 (process_request_thread)] basehttp.log_message line 212: "GET /static/images/hot-icon-small.png HTTP/1.1" 404 1834
2023-06-24 16:56:55 ERROR [9268-Thread-2 (process_request_thread)] log.log_response line 241: Internal Server Error: /blog/api/restful/teachers/
Traceback (most recent call last):
  File "C:\Users\MyNetdisk\AppData\Local\Programs\Python\Python311\Lib\site-packages\django\core\handlers\exception.py", line 55, in inner
    response = get_response(request)
               ^^^^^^^^^^^^^^^^^^^^^
  File "C:\Users\MyNetdisk\AppData\Local\Programs\Python\Python311\Lib\site-packages\django\core\handlers\base.py", line 197, in _get_response
    response = wrapped_callback(request, *callback_args, **callback_kwargs)
               ^^^^^^^^^^^^^^^^^^^^^^^^^^^^^^^^^^^^^^^^^^^^^^^^^^^^^^^^^^^^
  File "C:\Users\MyNetdisk\AppData\Local\Programs\Python\Python311\Lib\site-packages\django\views\decorators\csrf.py", line 56, in wrapper_view
    return view_func(*args, **kwargs)
           ^^^^^^^^^^^^^^^^^^^^^^^^^^
  File "C:\Users\MyNetdisk\AppData\Local\Programs\Python\Python311\Lib\site-packages\django\views\generic\base.py", line 104, in view
    return self.dispatch(request, *args, **kwargs)
           ^^^^^^^^^^^^^^^^^^^^^^^^^^^^^^^^^^^^^^^
  File "C:\Users\MyNetdisk\AppData\Local\Programs\Python\Python311\Lib\site-packages\rest_framework\views.py", line 509, in dispatch
    response = self.handle_exception(exc)
               ^^^^^^^^^^^^^^^^^^^^^^^^^^
  File "C:\Users\MyNetdisk\AppData\Local\Programs\Python\Python311\Lib\site-packages\rest_framework\views.py", line 469, in handle_exception
    self.raise_uncaught_exception(exc)
  File "C:\Users\MyNetdisk\AppData\Local\Programs\Python\Python311\Lib\site-packages\rest_framework\views.py", line 480, in raise_uncaught_exception
    raise exc
  File "C:\Users\MyNetdisk\AppData\Local\Programs\Python\Python311\Lib\site-packages\rest_framework\views.py", line 506, in dispatch
    response = handler(request, *args, **kwargs)
               ^^^^^^^^^^^^^^^^^^^^^^^^^^^^^^^^^
  File "C:\Users\MyNetdisk\AppData\Local\Programs\Python\Python311\Lib\site-packages\rest_framework\decorators.py", line 50, in handler
    return func(*args, **kwargs)
           ^^^^^^^^^^^^^^^^^^^^^
  File "D:\Project\DjangoBlogs\blog\views.py", line 226, in show_teachers_api_restful
    teachers = Teacher.objects.filter(
               ^^^^^^^^^^^^^^^^^^^^^^^
  File "C:\Users\MyNetdisk\AppData\Local\Programs\Python\Python311\Lib\site-packages\django\db\models\manager.py", line 87, in manager_method
    return getattr(self.get_queryset(), name)(*args, **kwargs)
           ^^^^^^^^^^^^^^^^^^^^^^^^^^^^^^^^^^^^^^^^^^^^^^^^^^^
  File "C:\Users\MyNetdisk\AppData\Local\Programs\Python\Python311\Lib\site-packages\django\db\models\query.py", line 1436, in filter
    return self._filter_or_exclude(False, args, kwargs)
           ^^^^^^^^^^^^^^^^^^^^^^^^^^^^^^^^^^^^^^^^^^^^
  File "C:\Users\MyNetdisk\AppData\Local\Programs\Python\Python311\Lib\site-packages\django\db\models\query.py", line 1454, in _filter_or_exclude
    clone._filter_or_exclude_inplace(negate, args, kwargs)
  File "C:\Users\MyNetdisk\AppData\Local\Programs\Python\Python311\Lib\site-packages\django\db\models\query.py", line 1461, in _filter_or_exclude_inplace
    self._query.add_q(Q(*args, **kwargs))
  File "C:\Users\MyNetdisk\AppData\Local\Programs\Python\Python311\Lib\site-packages\django\db\models\sql\query.py", line 1534, in add_q
    clause, _ = self._add_q(q_object, self.used_aliases)
                ^^^^^^^^^^^^^^^^^^^^^^^^^^^^^^^^^^^^^^^^
  File "C:\Users\MyNetdisk\AppData\Local\Programs\Python\Python311\Lib\site-packages\django\db\models\sql\query.py", line 1565, in _add_q
    child_clause, needed_inner = self.build_filter(
                                 ^^^^^^^^^^^^^^^^^^
  File "C:\Users\MyNetdisk\AppData\Local\Programs\Python\Python311\Lib\site-packages\django\db\models\sql\query.py", line 1415, in build_filter
    lookups, parts, reffed_expression = self.solve_lookup_type(arg, summarize)
                                        ^^^^^^^^^^^^^^^^^^^^^^^^^^^^^^^^^^^^^^
  File "C:\Users\MyNetdisk\AppData\Local\Programs\Python\Python311\Lib\site-packages\django\db\models\sql\query.py", line 1225, in solve_lookup_type
    _, field, _, lookup_parts = self.names_to_path(lookup_splitted, self.get_meta())
                                ^^^^^^^^^^^^^^^^^^^^^^^^^^^^^^^^^^^^^^^^^^^^^^^^^^^^
  File "C:\Users\MyNetdisk\AppData\Local\Programs\Python\Python311\Lib\site-packages\django\db\models\sql\query.py", line 1713, in names_to_path
    raise FieldError(
django.core.exceptions.FieldError: Cannot resolve keyword 'sno' into field. Choices are: bad_count, birth, good_count, intro, name, no, photo, sex, subject, subject_id
2023-06-24 16:56:55 ERROR [9268-Thread-2 (process_request_thread)] basehttp.log_message line 212: "GET /blog/api/restful/teachers/?sno=3 HTTP/1.1" 500 153946
